2019-12-24 15:58:53,157 ERROR: Exception on /edit_profile [POST] [in C:\Users\George\Desktop\flask\venv\lib\site-packages\flask\app.py:1891]
Traceback (most recent call last):
  File "C:\Users\George\Desktop\flask\venv\lib\site-packages\sqlalchemy\engine\base.py", line 1246, in _execute_context
    cursor, statement, parameters, context
  File "C:\Users\George\Desktop\flask\venv\lib\site-packages\sqlalchemy\engine\default.py", line 581, in do_execute
    cursor.execute(statement, parameters)
sqlite3.IntegrityError: UNIQUE constraint failed: user.username

The above exception was the direct cause of the following exception:

Traceback (most recent call last):
  File "C:\Users\George\Desktop\flask\venv\lib\site-packages\flask\app.py", line 2446, in wsgi_app
    response = self.full_dispatch_request()
  File "C:\Users\George\Desktop\flask\venv\lib\site-packages\flask\app.py", line 1951, in full_dispatch_request
    rv = self.handle_user_exception(e)
  File "C:\Users\George\Desktop\flask\venv\lib\site-packages\flask\app.py", line 1820, in handle_user_exception
    reraise(exc_type, exc_value, tb)
  File "C:\Users\George\Desktop\flask\venv\lib\site-packages\flask\_compat.py", line 39, in reraise
    raise value
  File "C:\Users\George\Desktop\flask\venv\lib\site-packages\flask\app.py", line 1949, in full_dispatch_request
    rv = self.dispatch_request()
  File "C:\Users\George\Desktop\flask\venv\lib\site-packages\flask\app.py", line 1935, in dispatch_request
    return self.view_functions[rule.endpoint](**req.view_args)
  File "C:\Users\George\Desktop\flask\venv\lib\site-packages\flask_login\utils.py", line 261, in decorated_view
    return func(*args, **kwargs)
  File "C:\Users\George\Desktop\flask\microblog\app\routes.py", line 91, in edit_profile
    db.session.commit()
  File "C:\Users\George\Desktop\flask\venv\lib\site-packages\sqlalchemy\orm\scoping.py", line 162, in do
    return getattr(self.registry(), name)(*args, **kwargs)
  File "C:\Users\George\Desktop\flask\venv\lib\site-packages\sqlalchemy\orm\session.py", line 1036, in commit
    self.transaction.commit()
  File "C:\Users\George\Desktop\flask\venv\lib\site-packages\sqlalchemy\orm\session.py", line 503, in commit
    self._prepare_impl()
  File "C:\Users\George\Desktop\flask\venv\lib\site-packages\sqlalchemy\orm\session.py", line 482, in _prepare_impl
    self.session.flush()
  File "C:\Users\George\Desktop\flask\venv\lib\site-packages\sqlalchemy\orm\session.py", line 2479, in flush
    self._flush(objects)
  File "C:\Users\George\Desktop\flask\venv\lib\site-packages\sqlalchemy\orm\session.py", line 2617, in _flush
    transaction.rollback(_capture_exception=True)
  File "C:\Users\George\Desktop\flask\venv\lib\site-packages\sqlalchemy\util\langhelpers.py", line 68, in __exit__
    compat.reraise(exc_type, exc_value, exc_tb)
  File "C:\Users\George\Desktop\flask\venv\lib\site-packages\sqlalchemy\util\compat.py", line 153, in reraise
    raise value
  File "C:\Users\George\Desktop\flask\venv\lib\site-packages\sqlalchemy\orm\session.py", line 2577, in _flush
    flush_context.execute()
  File "C:\Users\George\Desktop\flask\venv\lib\site-packages\sqlalchemy\orm\unitofwork.py", line 422, in execute
    rec.execute(self)
  File "C:\Users\George\Desktop\flask\venv\lib\site-packages\sqlalchemy\orm\unitofwork.py", line 589, in execute
    uow,
  File "C:\Users\George\Desktop\flask\venv\lib\site-packages\sqlalchemy\orm\persistence.py", line 236, in save_obj
    update,
  File "C:\Users\George\Desktop\flask\venv\lib\site-packages\sqlalchemy\orm\persistence.py", line 996, in _emit_update_statements
    statement, multiparams
  File "C:\Users\George\Desktop\flask\venv\lib\site-packages\sqlalchemy\engine\base.py", line 982, in execute
    return meth(self, multiparams, params)
  File "C:\Users\George\Desktop\flask\venv\lib\site-packages\sqlalchemy\sql\elements.py", line 287, in _execute_on_connection
    return connection._execute_clauseelement(self, multiparams, params)
  File "C:\Users\George\Desktop\flask\venv\lib\site-packages\sqlalchemy\engine\base.py", line 1101, in _execute_clauseelement
    distilled_params,
  File "C:\Users\George\Desktop\flask\venv\lib\site-packages\sqlalchemy\engine\base.py", line 1250, in _execute_context
    e, statement, parameters, cursor, context
  File "C:\Users\George\Desktop\flask\venv\lib\site-packages\sqlalchemy\engine\base.py", line 1476, in _handle_dbapi_exception
    util.raise_from_cause(sqlalchemy_exception, exc_info)
  File "C:\Users\George\Desktop\flask\venv\lib\site-packages\sqlalchemy\util\compat.py", line 398, in raise_from_cause
    reraise(type(exception), exception, tb=exc_tb, cause=cause)
  File "C:\Users\George\Desktop\flask\venv\lib\site-packages\sqlalchemy\util\compat.py", line 152, in reraise
    raise value.with_traceback(tb)
  File "C:\Users\George\Desktop\flask\venv\lib\site-packages\sqlalchemy\engine\base.py", line 1246, in _execute_context
    cursor, statement, parameters, context
  File "C:\Users\George\Desktop\flask\venv\lib\site-packages\sqlalchemy\engine\default.py", line 581, in do_execute
    cursor.execute(statement, parameters)
sqlalchemy.exc.IntegrityError: (sqlite3.IntegrityError) UNIQUE constraint failed: user.username
[SQL: UPDATE user SET username=?, about_me=? WHERE user.id = ?]
[parameters: ('234', '654321', 3)]
(Background on this error at: http://sqlalche.me/e/gkpj)
2019-12-26 14:39:22,422 INFO: Microblog startup [in C:\Users\George\Desktop\flask\microblog\app\__init__.py:52]
2019-12-26 14:42:15,732 INFO: Microblog startup [in C:\Users\George\Desktop\flask\microblog\app\__init__.py:52]
2019-12-26 14:42:55,498 INFO: Microblog startup [in C:\Users\George\Desktop\flask\microblog\app\__init__.py:52]
2019-12-26 14:43:29,860 INFO: Microblog startup [in C:\Users\George\Desktop\flask\microblog\app\__init__.py:52]
2019-12-26 14:43:31,571 INFO: Microblog startup [in C:\Users\George\Desktop\flask\microblog\app\__init__.py:52]
2019-12-26 14:46:11,761 INFO: Microblog startup [in C:\Users\George\Desktop\flask\microblog\app\__init__.py:52]
2019-12-26 14:46:13,449 INFO: Microblog startup [in C:\Users\George\Desktop\flask\microblog\app\__init__.py:52]
2019-12-26 14:47:22,634 INFO: Microblog startup [in C:\Users\George\Desktop\flask\microblog\app\__init__.py:52]
2019-12-26 14:47:24,268 INFO: Microblog startup [in C:\Users\George\Desktop\flask\microblog\app\__init__.py:52]
2019-12-26 14:48:10,828 INFO: Microblog startup [in C:\Users\George\Desktop\flask\microblog\app\__init__.py:52]
2019-12-26 14:48:12,498 INFO: Microblog startup [in C:\Users\George\Desktop\flask\microblog\app\__init__.py:52]
